Workbook

Sheet MATING_PLAN_SAFE
A1: Note
A2: No MATING_PLAN found to filter; safe plan not generated.

Sheet RAM_ASSIGNMENT_SAFE
A1: RamID | B1: RamName | C1: RamTag | D1: RamPen | E1: AssignedEwes(top choice) | F1: Eligible | G1: Notes

Sheet RULES_ENFORCED
A1: RuleID | B1: Rule | C1: Status | D1: Rationale
A2: R1 | B2: Exclude placeholder/unknown 'twin rams' from recommendations | C2: ON | D2: They are clutter/noise and may be lambs or untracked.
A3: R2 | B3: Only recommend adult rams (>=9 months) with known DOB | C3: ON | D3: Prevents recommending ram lambs / unknown age sires.
A4: R3 | B4: Geriatric safety: If ewe age >= 6 years, exclude Ram 00110 (Orange Tag) | C4: ON | D4: Reduce dystocia risk from large terminal sire on older ewes.
A5: R4 | B5: Only recommend rams marked 'Eligible' | C5: ON | D5: Central toggle for future terminal/maternal/health exclusions.

Sheet RAM_ELIGIBILITY
A1: RamID | B1: Name | C1: Tag | D1: Pen | E1: AgeYears | F1: DOBKnown | G1: IsAdult(>=9mo) | H1: IsPlaceholder | I1: Eligible | J1: Reason
A2: TAG_00110 | B2: 00110 | C2: 00110 | D2: Pen 1 | F2: FALSE | G2: FALSE | H2: FALSE | I2: FALSE | J2: DOB missing, Not adult
A3: P1_TWIN_RAM_BROWNWHITE | B3: Twin ram (brown & white) | D3: Pen 1 | F3: FALSE | G3: FALSE | H3: TRUE | I3: FALSE | J3: DOB missing, Not adult, Placeholder/twin
A4: P1_TWIN_RAM_BLACKWHITE | B4: Twin ram (black & white) | D4: Pen 1 | F4: FALSE | G4: FALSE | H4: TRUE | I4: FALSE | J4: DOB missing, Not adult, Placeholder/twin
A5: P1_RAM_LAMB_BROWNWHITE_01 | B5: Ram lamb (brown & white) | D5: Pen 1 | F5: FALSE | G5: FALSE | H5: TRUE | I5: FALSE | J5: DOB missing, Not adult, Placeholder/twin
A6: JERK_FACE | B6: Jerk Face | D6: Pen 2 | F6: FALSE | G6: FALSE | H6: FALSE | I6: FALSE | J6: DOB missing, Not adult
A7: MERRIE | B7: Merrie | C7: 00016 | D7: Pen 3 | F7: FALSE | G7: FALSE | H7: FALSE | I7: FALSE | J7: DOB missing, Not adult
A8: CHARLIE | B8: Charlie | D8: Pen 3 | F8: FALSE | G8: FALSE | H8: FALSE | I8: FALSE | J8: DOB missing, Not adult
A9: P4_RAM_LAMB_WHITE_01 | B9: Ram lamb (white) | D9: Pen 4 | F9: FALSE | G9: FALSE | H9: FALSE | I9: FALSE | J9: DOB missing, Not adult
A10: TAG_0113 | B10: 113 | C10: 113 | D10: Pen 5 | F10: FALSE | G10: FALSE | H10: FALSE | I10: FALSE | J10: DOB missing, Not adult
A11: MC08 | B11: Mc08 | C11: Mc08 | D11: Pen 6 | F11: FALSE | G11: FALSE | H11: FALSE | I11: FALSE | J11: DOB missing, Not adult
A12: TAG_0009 | B12: 09 | C12: 09 | D12: Goose Pen | F12: FALSE | G12: FALSE | H12: FALSE | I12: FALSE | J12: DOB missing, Not adult
A13: TAG_0006 | B13: 06 | C13: 06 | D13: Goose Pen | F13: FALSE | G13: FALSE | H13: FALSE | I13: FALSE | J13: DOB missing, Not adult
A14: GP_RAM_LAMB_FAWN_01 | B14: Ram lamb (fawn to light tan) | D14: Goose Pen | F14: FALSE | G14: FALSE | H14: FALSE | I14: FALSE | J14: DOB missing, Not adult
A15: BUCK_2433 | B15: Buck | C15: 2433 | D15: Tree Fort | F15: FALSE | G15: FALSE | H15: FALSE | I15: FALSE | J15: DOB missing, Not adult

Sheet MATING_PLAN
A1: EwePen | B1: EweName | C1: EweTag | D1: EweID | E1: ChoiceRank | F1: RamName | G1: RamTag | H1: RamPen | I1: RamID | J1: Score | K1: BaseScore | L1: Penalty | M1: ConstraintNote | N1: MissingRamData
A2: Pen 1 | B2: Azure | C2: 20 | D2: AZURE_0020 | E2: 1 | F2: 00110 | G2: 00110 | H2: Pen 1 | I2: TAG_00110 | J2: 0.5 | K2: 0.5 | L2: 0 | N2: Hardiness, Meat, Hair
A3: Pen 1 | B3: Azure | C3: 20 | D3: AZURE_0020 | E3: 2 | F3: Twin ram (brown & white) | H3: Pen 1 | I3: P1_TWIN_RAM_BROWNWHITE | J3: 0.5 | K3: 0.5 | L3: 0 | N3: Hardiness, Meat, Hair
A4: Pen 1 | B4: Azure | C4: 20 | D4: AZURE_0020 | E4: 3 | F4: Twin ram (black & white) | H4: Pen 1 | I4: P1_TWIN_RAM_BLACKWHITE | J4: 0.5 | K4: 0.5 | L4: 0 | N4: Hardiness, Meat, Hair
A5: Pen 3 | B5: Broken Tail | D5: BROKEN_TAIL | E5: 1 | F5: 00110 | G5: 00110 | H5: Pen 1 | I5: TAG_00110 | J5: 0.5 | K5: 0.5 | L5: 0 | N5: Hardiness, Meat, Hair
A6: Pen 3 | B6: Broken Tail | D6: BROKEN_TAIL | E6: 2 | F6: Twin ram (brown & white) | H6: Pen 1 | I6: P1_TWIN_RAM_BROWNWHITE | J6: 0.5 | K6: 0.5 | L6: 0 | N6: Hardiness, Meat, Hair
A7: Pen 3 | B7: Broken Tail | D7: BROKEN_TAIL | E7: 3 | F7: Twin ram (black & white) | H7: Pen 1 | I7: P1_TWIN_RAM_BLACKWHITE | J7: 0.5 | K7: 0.5 | L7: 0 | N7: Hardiness, Meat, Hair
A8: Pen 3 | B8: Charlie's ewe | D8: CHARLIES_EWE_1 | E8: 1 | F8: 00110 | G8: 00110 | H8: Pen 1 | I8: TAG_00110 | J8: 0.5 | K8: 0.5 | L8: 0 | N8: Hardiness, Meat, Hair
A9: Pen 3 | B9: Charlie's ewe | D9: CHARLIES_EWE_1 | E9: 2 | F9: Twin ram (brown & white) | H9: Pen 1 | I9: P1_TWIN_RAM_BROWNWHITE | J9: 0.5 | K9: 0.5 | L9: 0 | N9: Hardiness, Meat, Hair
A10: Pen 3 | B10: Charlie's ewe | D10: CHARLIES_EWE_1 | E10: 3 | F10: Twin ram (black & white) | H10: Pen 1 | I10: P1_TWIN_RAM_BLACKWHITE | J10: 0.5 | K10: 0.5 | L10: 0 | N10: Hardiness, Meat, Hair
A11: Pen 1 | B11: Charlie's ewe 2 | D11: CHARLIES_EWE_2 | E11: 1 | F11: 00110 | G11: 00110 | H11: Pen 1 | I11: TAG_00110 | J11: 0.5 | K11: 0.5 | L11: 0 | N11: Hardiness, Meat, Hair
A12: Pen 1 | B12: Charlie's ewe 2 | D12: CHARLIES_EWE_2 | E12: 2 | F12: Twin ram (brown & white) | H12: Pen 1 | I12: P1_TWIN_RAM_BROWNWHITE | J12: 0.5 | K12: 0.5 | L12: 0 | N12: Hardiness, Meat, Hair
A13: Pen 1 | B13: Charlie's ewe 2 | D13: CHARLIES_EWE_2 | E13: 3 | F13: Twin ram (black & white) | H13: Pen 1 | I13: P1_TWIN_RAM_BLACKWHITE | J13: 0.5 | K13: 0.5 | L13: 0 | N13: Hardiness, Meat, Hair
A14: Tree Fort | B14: Charlie's ewe 3 | D14: CHARLIES_EWE_3 | E14: 1 | F14: 00110 | G14: 00110 | H14: Pen 1 | I14: TAG_00110 | J14: 0.5 | K14: 0.5 | L14: 0 | N14: Hardiness, Meat, Hair
A15: Tree Fort | B15: Charlie's ewe 3 | D15: CHARLIES_EWE_3 | E15: 2 | F15: Twin ram (brown & white) | H15: Pen 1 | I15: P1_TWIN_RAM_BROWNWHITE | J15: 0.5 | K15: 0.5 | L15: 0 | N15: Hardiness, Meat, Hair
A16: Tree Fort | B16: Charlie's ewe 3 | D16: CHARLIES_EWE_3 | E16: 3 | F16: Twin ram (black & white) | H16: Pen 1 | I16: P1_TWIN_RAM_BLACKWHITE | J16: 0.5 | K16: 0.5 | L16: 0 | N16: Hardiness, Meat, Hair
A17: Pen 6 | B17: Elsie | D17: ELSIE | E17: 1 | F17: 00110 | G17: 00110 | H17: Pen 1 | I17: TAG_00110 | J17: 0.5 | K17: 0.5 | L17: 0 | N17: Hardiness, Meat, Hair
A18: Pen 6 | B18: Elsie | D18: ELSIE | E18: 2 | F18: Twin ram (brown & white) | H18: Pen 1 | I18: P1_TWIN_RAM_BROWNWHITE | J18: 0.5 | K18: 0.5 | L18: 0 | N18: Hardiness, Meat, Hair
A19: Pen 6 | B19: Elsie | D19: ELSIE | E19: 3 | F19: Twin ram (black & white) | H19: Pen 1 | I19: P1_TWIN_RAM_BLACKWHITE | J19: 0.5 | K19: 0.5 | L19: 0 | N19: Hardiness, Meat, Hair
A20: Pen 4 | B20: Fms daughter | D20: FMS_DAUGHTER | E20: 1 | F20: 00110 | G20: 00110 | H20: Pen 1 | I20: TAG_00110 | J20: 0.5 | K20: 0.5 | L20: 0 | N20: Hardiness, Meat, Hair
A21: Pen 4 | B21: Fms daughter | D21: FMS_DAUGHTER | E21: 2 | F21: Twin ram (brown & white) | H21: Pen 1 | I21: P1_TWIN_RAM_BROWNWHITE | J21: 0.5 | K21: 0.5 | L21: 0 | N21: Hardiness, Meat, Hair
A22: Pen 4 | B22: Fms daughter | D22: FMS_DAUGHTER | E22: 3 | F22: Twin ram (black & white) | H22: Pen 1 | I22: P1_TWIN_RAM_BLACKWHITE | J22: 0.5 | K22: 0.5 | L22: 0 | N22: Hardiness, Meat, Hair
A23: Pen 4 | B23: Gigi | D23: GIGI | E23: 1 | F23: 00110 | G23: 00110 | H23: Pen 1 | I23: TAG_00110 | J23: 0.5 | K23: 0.5 | L23: 0 | N23: Hardiness, Meat, Hair
A24: Pen 4 | B24: Gigi | D24: GIGI | E24: 2 | F24: Twin ram (brown & white) | H24: Pen 1 | I24: P1_TWIN_RAM_BROWNWHITE | J24: 0.5 | K24: 0.5 | L24: 0 | N24: Hardiness, Meat, Hair
A25: Pen 4 | B25: Gigi | D25: GIGI | E25: 3 | F25: Twin ram (black & white) | H25: Pen 1 | I25: P1_TWIN_RAM_BLACKWHITE | J25: 0.5 | K25: 0.5 | L25: 0 | N25: Hardiness, Meat, Hair
A26: Pen 3 | B26: Nori | C26: 0029 | D26: NORI_0029 | E26: 1 | F26: 00110 | G26: 00110 | H26: Pen 1 | I26: TAG_00110 | J26: 0.5 | K26: 0.5 | L26: 0 | N26: Hardiness, Meat, Hair
A27: Pen 3 | B27: Nori | C27: 0029 | D27: NORI_0029 | E27: 2 | F27: Twin ram (brown & white) | H27: Pen 1 | I27: P1_TWIN_RAM_BROWNWHITE | J27: 0.5 | K27: 0.5 | L27: 0 | N27: Hardiness, Meat, Hair
A28: Pen 3 | B28: Nori | C28: 0029 | D28: NORI_0029 | E28: 3 | F28: Twin ram (black & white) | H28: Pen 1 | I28: P1_TWIN_RAM_BLACKWHITE | J28: 0.5 | K28: 0.5 | L28: 0 | N28: Hardiness, Meat, Hair
A29: Pen 4 | B29: Ewe lamb (black) | D29: P4_EWE_LAMB_BLACK_01 | E29: 1 | F29: 00110 | G29: 00110 | H29: Pen 1 | I29: TAG_00110 | J29: 0.5 | K29: 0.5 | L29: 0 | N29: Hardiness, Meat, Hair
A30: Pen 4 | B30: Ewe lamb (black) | D30: P4_EWE_LAMB_BLACK_01 | E30: 2 | F30: Twin ram (brown & white) | H30: Pen 1 | I30: P1_TWIN_RAM_BROWNWHITE | J30: 0.5 | K30: 0.5 | L30: 0 | N30: Hardiness, Meat, Hair
A31: Pen 4 | B31: Ewe lamb (black) | D31: P4_EWE_LAMB_BLACK_01 | E31: 3 | F31: Twin ram (black & white) | H31: Pen 1 | I31: P1_TWIN_RAM_BLACKWHITE | J31: 0.5 | K31: 0.5 | L31: 0 | N31: Hardiness, Meat, Hair
A32: Pen 4 | B32: Serendipity | C32: 30 | D32: SERENDIPITY | E32: 1 | F32: 00110 | G32: 00110 | H32: Pen 1 | I32: TAG_00110 | J32: 0.5 | K32: 0.5 | L32: 0 | N32: Hardiness, Meat, Hair
A33: Pen 4 | B33: Serendipity | C33: 30 | D33: SERENDIPITY | E33: 2 | F33: Twin ram (brown & white) | H33: Pen 1 | I33: P1_TWIN_RAM_BROWNWHITE | J33: 0.5 | K33: 0.5 | L33: 0 | N33: Hardiness, Meat, Hair
A34: Pen 4 | B34: Serendipity | C34: 30 | D34: SERENDIPITY | E34: 3 | F34: Twin ram (black & white) | H34: Pen 1 | I34: P1_TWIN_RAM_BLACKWHITE | J34: 0.5 | K34: 0.5 | L34: 0 | N34: Hardiness, Meat, Hair
A35: Pen 5 | B35: 02 | C35: 02 | D35: TAG_0002 | E35: 1 | F35: 00110 | G35: 00110 | H35: Pen 1 | I35: TAG_00110 | J35: 0.5 | K35: 0.5 | L35: 0 | N35: Hardiness, Meat, Hair
A36: Pen 5 | B36: 02 | C36: 02 | D36: TAG_0002 | E36: 2 | F36: Twin ram (brown & white) | H36: Pen 1 | I36: P1_TWIN_RAM_BROWNWHITE | J36: 0.5 | K36: 0.5 | L36: 0 | N36: Hardiness, Meat, Hair
A37: Pen 5 | B37: 02 | C37: 02 | D37: TAG_0002 | E37: 3 | F37: Twin ram (black & white) | H37: Pen 1 | I37: P1_TWIN_RAM_BLACKWHITE | J37: 0.5 | K37: 0.5 | L37: 0 | N37: Hardiness, Meat, Hair
A38: Pen 1 | B38: 003 | C38: 003 | D38: TAG_0003 | E38: 1 | F38: 00110 | G38: 00110 | H38: Pen 1 | I38: TAG_00110 | J38: 0.5 | K38: 0.5 | L38: 0 | N38: Hardiness, Meat, Hair
A39: Pen 1 | B39: 003 | C39: 003 | D39: TAG_0003 | E39: 2 | F39: Twin ram (brown & white) | H39: Pen 1 | I39: P1_TWIN_RAM_BROWNWHITE | J39: 0.5 | K39: 0.5 | L39: 0 | N39: Hardiness, Meat, Hair
A40: Pen 1 | B40: 003 | C40: 003 | D40: TAG_0003 | E40: 3 | F40: Twin ram (black & white) | H40: Pen 1 | I40: P1_TWIN_RAM_BLACKWHITE | J40: 0.5 | K40: 0.5 | L40: 0 | N40: Hardiness, Meat, Hair
...

Sheet RAM_ASSIGNMENT
A1: RamID | B1: RamName | C1: RamTag | D1: RamPen | E1: AssignedEwes(top choice)
A2: TAG_00110 | B2: 00110 | C2: 00110 | D2: Pen 1 | E2: 27

Sheet COSTS_RAW_2022_2026
A1: Statistics: | B1: Tag Number | C1: Sheep Name | D1: Gender | E1: Present/Sold | F1: Date of Birth | G1: Date Aquired | H1: Date Sold/Died | I1: Months Old | J1: Days Owned | K1: Total Cost While Owned | L1: Price Paid | M1: Price Received | N1: Profit/Loss | O1: Paint Color | P1: Breed %s | R1: Sire | S1: Dam | T1: Breeder | U1: Number of babies total | V1: Number of Lambs this year | W1: Number survived till weaned (this year) | X1: Birth Weight | Y1: 60 day weight | Z1: CDT (1) | AA1: CDT (2) | AB1: CDT (2021 Booster) | AC1: Link to Photo | AD1: Comments | AK1: Todays Date
A2: Todays Date: | C2: Midnight Snack | D2: Ram | E2: S | F2: 3/13/2021 | G2: 5/24/2021 | I2: 57 | J2: 1689 | K2: #REF! | L2: 0.00 | P2: 100% Katahdin | AD2: All Black | AK2: 1/7/2026
A3: 1/7/2026 | C3: Black Rock | E3: P | F3: 3/13/2021 | G3: 5/24/2021 | I3: 55 | J3: 1689 | K3: #REF! | L3: 0.00 | P3: 100% Katahdin | AD3: Black With a white Blaze on his head.
A4: Cost/Sheep/Day | C4: BrownKnee | D4: Ram | E4: P | F4: 11/1/2015 | G4: 11/1/2015 | I4: 122 | J4: 3720 | K4: #REF! | L4: 230.00 | P4: 75% st augustine 25% Katahdin | R4: St augustine Ram 1 | S4: Half Katahdin Half St Augustine ewe | T4: Carol Posley/Fairmeadow | AD4: Docile. Meaty - easily 300lbs
A5: #REF! | C5: Anna | D5: Ewe | E5: D | F5: 4/24/2021 | G5: 4/24/2021 | I5: 56 | J5: 1719 | K5: #REF! | L5: 0.00 | O5: Yellow | P5: 54.75% St Augustine 46.25% Katahdin | R5: Sir Loin | S5: Brownknee | T5: Ken | AD5: Bottle Baby
C6: Sheep Number | D6: Ewe | E6: P | F6: 6/1/2015 | G6: 6/1/2015 | I6: 127 | J6: 3873 | K6: #REF! | L6: 200.00 | O6: Purple | P6: Katahdin 100% | R6: Katahdin Ewe 2 | S6: Katahdin Ewe 1 | T6: Ed Maddox | V6: 3 | W6: 2 | AD6: Our Friendly Matriarch
C7: Sir Loin | D7: Ram | E7: P | F7: 2/14/2021 | G7: 10/1/2021 | I7: 51 | J7: 1559 | K7: #REF! | L7: 150.00
C8: Anna's Big One | D8: Ewe | E8: P | F8: 4/10/2021 | G8: 4/10/2021 | I8: 56 | J8: 1733 | K8: #REF! | L8: 0.00 | O8: Purple | P8: 37.5% St Augustine 62.5% katahdin | R8: Sir Loin | S8: Anna | T8: Ken
C9: Half Tail | D9: Ewe | E9: P | F9: 5/14/2020 | G9: 5/14/2021 | I9: 55 | J9: 1699 | K9: #REF! | L9: 175.00 | P9: 50%Jacob 50% Babydoll
C10: Hersheys | D10: Ewe | E10: P | F10: 1/24/2021 | G10: 4/18/2021 | I10: 56 | J10: 1725 | K10: #REF! | L10: 200.00 | P10: 50% Dorper 50% katahdin | R10: Dorper Ram 1 | S10: Katahdin Ewe 1 | T10: Maria Tracy (Heather farms) | AD10: Purchased for Milk Production
C11: Sugar | D11: Ewe | E11: P | F11: 1/4/2019 | G11: 1/4/2019 | I11: 84 | J11: 2560 | K11: #REF! | L11: 0.00 | O11: Yellow | P11: 37.5 st augustine 62.5% katahdin | R11: Sir Loin | S11: Anna | T11: Ken | U11: 2 | V11: 2 | AD11: Rejected one lamb violently(21)
C12: Razzle | D12: Ewe | E12: P | F12: 1/18/2018 | G12: 1/18/2018 | I12: 95 | J12: 2911 | K12: #REF! | L12: 0.00
C13: Frazzle | D13: Ewe | E13: P | F13: 1/13/2021 | G13: 4/18/2021 | I13: 56 | J13: 1725 | K13: #REF! | L13: 200.00 | P13: 50% Dorper 50% katahdin | R13: Dorper Ram 2 | S13: Katahdin Ewe 2 | T13: Maria Tracy (Heather farms) | AD13: Purchased for Milk Production
C14: Boots | D14: Ewe | E14: P | F14: 1/1/2020 | G14: 1/1/2020 | I14: 72 | J14: 2198 | K14: #REF! | L14: 0.00 | P14: 25% BBB 12.5% Auction 25% Katahdin and 37.5% St Augustine | R14: Sir Loin | S14: Sugar | T14: Ken | U14: 3 | V14: 3 | AD14: Rejected her male, lost one of the triplets (21)
C15: Rose Baby 2 | D15: Ewe | E15: S | F15: 4/20/2021 | G15: 4/20/2021 | I15: 56 | J15: 1723 | K15: #REF! | L15: 0.00 | O15: Green | P15: 12.5 bbb 6.25 auction 31.5 katahdin 37.5 st augustine | R15: Sir Loin | S15: Rose | T15: Ken
C16: Sugar Baby -1 | D16: Ewe | E16: S | F16: 1/18/2021 | G16: 1/18/2021 | I16: 59 | J16: 1815 | K16: #REF! | L16: 0.00 | O16: Black | P16: 37.5% Katahdin. 12.5% BBB, 37.5 St Augustine, 12.5% Auction Breed | R16: Sir Loin | S16: Sugar Baby | T16: Ken
C17: Trouble | D17: Ewe | E17: P | F17: 1/19/2020 | G17: 1/19/2020 | I17: 71 | J17: 2180 | K17: #REF! | L17: 0.00 | O17: Black | P17: 37.5% Katahdin. 12.5% BBB, 37.5 St Augustine, 12.5% Auction Breed | R17: Sir Loin | S17: Sugar | T17: Ken | U17: 0 | V17: 0 | AD17: Fairly Wooly. Stocky,
C18: Shaggy | D18: Ewe | E18: P | F18: 7/1/2020 | G18: 7/1/2020 | I18: 66 | J18: 2016 | K18: #REF! | L18: 0.00 | P18: 50% Dorper, 37.5% St Augustine 12.5% Katahdin | R18: Sir Loin | S18: Haley Lawson | T18: Ken | U18: 0 | V18: 0 | W18: 0 | AD18: Small, and wooley. Will breed, and release. Nibbles your clothing.
C19: Razzle | D19: Ram | E19: S | F19: 3/12/2013 | G19: 3/12/2013 | H19: 5/12/2015 | J19: 791 | L19: 30.00 | P19: Barbados Black Belly | R19: Auction | S19: Auction | T19: Auction | W19: m
C20: Frazzle | D20: Ewe | E20: S | F20: 9/12/2013 | G20: 3/3/2014 | H20: 5/20/2020 | J20: 2270 | P20: Auction Breed X Katahdin | R20: Auction | S20: Auction | T20: Auction
C21: Haley Lawson | D21: Ewe | E21: S | F21: 1/1/2019 | G21: 1/1/2019 | H21: 12/1/2020 | P21: 50% Cracker 50% Unknown | R21: X | S21: X | T21: Haley Lawson | U21: 1 | V21: 0 | W21: 1 | AD21: Slow growing.
C22: Sugar | D22: Ewe | E22: S | F22: 11/1/2014 | G22: 1/1/2019 | H22: 1/1/2019 | P22: 50% Katahdin 25% Barbados Black Belly 25% Auction Breed | R22: Clyde | S22: Hershey | T22: Greg | V22: 0 | W22: 0
C23: Deceased | D23: Ram | E23: S-D | F23: 4/10/2021 | G23: 4/10/2021 | H23: 4/10/2021 | I23: 0 | J23: 0 | K23: #REF! | P23: 37.5% St Augustine 62.5% katahdin | R23: Sir Loin | S23: Anna | T23: Ken
C24: Brownknee - 2 | D24: Ram | E24: S-D | F24: 4/24/2021 | G24: 4/24/2021 | H24: 4/24/2021 | I24: 0 | J24: 0 | K24: #REF! | O24: Yellow | P24: 54.75% St. Autustine 46.25% Katahdin | R24: Sir Loin | S24: Brownknee | T24: Ken
C25: Elsie | D25: Ewe | E25: P | F25: 1/1/2020 | G25: 4/1/2021 | I25: 57 | J25: 1742 | K25: #REF! | L25: 200.00
C26: Chipolte Spicy Boi (BT1) | D26: Ewe | E26: P | F26: 1/1/2020 | G26: 1/1/2020 | I26: 72 | J26: 2198 | K26: #REF! | L26: 0.00
C27: Kaladin | D27: Ewe | E27: P | F27: 1/1/2021 | G27: 1/6/2022 | I27: 48 | J27: 1462 | K27: #REF! | L27: 125.00 | P27: 50% Tunis 50% Cotswald | S27: Etta Lee
C28: Current Sheep | E28: Total Sheep | F28: Sold Sheep
A31: Current Sheep Count: | C31: 16 | E31: 27 | F31: 7
A32: 16
A35: Total CPD for ALL sheep:
A36: #REF!

Sheet WEIGHTS_30D_RAW_2022
A1: Sheep Name | C1: Gender | D1: Color | E1: Heart Girth | F1: Body Length | G1: Weight | H1: ADG | I1: Heart Girth | J1: Body Length | K1: Weight | L1: ADG | M1: HEART GIRTH x HEART GIRTH x BODY LENGTH / 300 = Weight
A2: Ewes | G2: 3-26-22 | K2: Date
A3: Serendipity | C3: e | D3: Black with white crown | E3: 15.25 | F3: 14.5 | G3: 11.24052083
A4: Black Beauty | C4: e | D4: Black with white speckles | E4: 23 | F4: 22 | G4: 38.79333333 | H4: 0.558
A6: Rams
A7: Black Rock (Elsie's Brother) | C7: r | D7: All black | E7: 23 | F7: 20 | G7: 35.26666667
A8: Spicy Boi (BT1) | C8: r | D8: Brn tips on ear | E8: 25.75 | F8: 23.5 | G8: 51.93989583 | H8: 0.774
A9: Black spot on ear | C9: E | E9: 33 | F9: 36.5 | G9: 132.495 | H9: 1.3
A31: 30 day Weights 2022

Sheet IMPORT_LOG_2026_01_07_V3
A1: Imported On | B1: File | C1: Type | D1: Parsed Name | E1: Tag | F1: Rows Added (PERF) | G1: Rows Added (MED) | H1: Note
A2: 2026-01-07 | B2: Manatee Creek - FM1.csv | C2: ANIMAL_CSV | D2: FM1 | F2: 0 | G2: 0 | H2: Imported & merged
A3: 2026-01-07 | B3: Manatee Creek - FM (E).csv | C3: ANIMAL_CSV | D3: FM | E3: Ga1568 | F3: 0 | G3: 0 | H3: Imported & merged
A4: 2026-01-07 | B4: Manatee Creek - Serendipity (E).csv | C4: ANIMAL_CSV | D4: Serendipity | F4: 0 | G4: 0 | H4: Imported & merged
A5: 2026-01-07 | B5: Manatee Creek - Pretzal (E).csv | C5: ANIMAL_CSV | D5: Pretzal | F5: 0 | G5: 0 | H5: Imported & merged
A6: 2026-01-07 | B6: Manatee Creek - 2022 30 day weights.csv | C6: RAW_TABLE | F6: 0 | G6: 0 | H6: Imported raw 30-day weights table
A7: 2026-01-07 | B7: Manatee Creek - Costs.csv | C7: RAW_TABLE | F7: 0 | G7: 0 | H7: Imported raw costs table

Sheet IMPORT_LOG_2026_01_07_V2
A1: Imported On | B1: File | C1: Parsed Name | D1: Tag | E1: Sex | F1: DOB | G1: Sire | H1: Dam | I1: BreedMix Sum | J1: Famacha Rows | K1: FEC Rows | L1: Note/Skip
A2: 2026-01-07 | B2: Manatee Creek - Banana.csv | C2: Banana | E2: E | G2: Sir Loin | H2: Anna | I2: 100 | J2: 0 | K2: 0 | L2: parsed
A3: 2026-01-07 | B3: Manatee Creek - Black Spot on Ear Daughter (e).csv | C3: Black Spot on Ear Daughter | E3: E | G3: Sir Loin | H3: BSOE | I3: 100 | J3: 0 | K3: 0 | L3: parsed
A4: 2026-01-07 | B4: Manatee Creek - Chipolte Spicy Boi BT1 (R).csv | C4: Chipoitle Spicy Boi (Bt1) | E4: R | F4: 2-7-22 | G4: Sir Loin | H4: Broken Tail | I4: 450 | J4: 0 | K4: 0 | L4: parsed
A5: 2026-01-07 | B5: Manatee Creek - Black Spot on Ear (E).csv | C5: Black Spot on Ear | E5: E | G5: Sir Loin | H5: Two Pence | I5: 100 | J5: 0 | K5: 0 | L5: parsed
A6: 2026-01-07 | B6: Manatee Creek - Broken Tail.csv | C6: Broken Tail | E6: E | G6: Sir Loin | H6: Half Tail | I6: 93.75 | J6: 0 | K6: 0 | L6: parsed
A7: 2026-01-07 | B7: Manatee Creek - Pretzal (E).csv | C7: Pretzal | E7: E | F7: 1-24-22 | G7: ? | H7: ? | J7: 0 | K7: 0 | L7: parsed
A8: 2026-01-07 | B8: Manatee Creek - Third Ewe (E).csv | C8: Third Ewe | E8: E | G8: Sir Loin | H8: Other Ewe | I8: 575 | J8: 0 | K8: 0 | L8: parsed
A9: 2026-01-07 | B9: Manatee Creek - S'more.csv | C9: S'More | E9: R | F9: 1-14-21 | I9: 100 | J9: 0 | K9: 0 | L9: parsed
A10: 2026-01-07 | B10: Manatee Creek - Banana Split (E).csv | C10: Black Spot on Ear Daughter | E10: E | G10: Sir Loin | H10: Black Spot on Ear | I10: 575 | J10: 0 | K10: 0 | L10: parsed
A11: 2026-01-07 | B11: Manatee Creek - FM (E).csv | C11: FM | D11: Ga1568 | E11: E | F11: 2-14-21 | G11: Tunis | H11: Cotswald | I11: 100 | J11: 0 | K11: 0 | L11: parsed
A12: 2026-01-07 | B12: Manatee Creek - FM1.csv | C12: FM1 | G12: Sir Loin | H12: FM | I12: 100 | J12: 0 | K12: 0 | L12: parsed
A13: 2026-01-07 | B13: Manatee Creek - Serendipity (E).csv | C13: Serendipity | E13: E | F13: 3-25-22 | G13: Sirloin | H13: Shaggy | I13: 100 | J13: 0 | K13: 0 | L13: parsed
A14: 2026-01-07 | B14: Manatee Creek - 2241 (e).csv | C14: 2241 | D14: 2241 | I14: 100 | J14: 1 | K14: 0 | L14: parsed
A15: 2026-01-07 | B15: Manatee Creek - OAV 2223 (r) (Kelsier).csv | C15: Oav 2223 | E15: R | F15: 12-21-22 | I15: 100 | J15: 0 | K15: 9 | L15: parsed
A16: 2026-01-07 | B16: Manatee Creek - GG (Gentle Giant).csv | C16: Fl51870 - 0502 (Pen 1-2) | E16: 0 | I16: 100 | J16: 1 | K16: 0 | L16: parsed
A17: 2026-01-07 | B17: Manatee Creek - Elsie (E).csv | C17: Elsie | E17: E | F17: 2-8-22 | G17: Well Done | H17: Halftail | I17: 100 | J17: 2 | K17: 0 | L17: parsed
A18: 2026-01-07 | B18: Manatee Creek - Buck (Kat x Awassi).csv | C18: Kat x awassi | I18: 100 | J18: 0 | K18: 0 | L18: parsed
A19: 2026-01-07 | B19: Manatee Creek - Serendipity.csv | C19: Serendipity | D19: 30 | G19: Sir Loin | H19: Shaggy | I19: 100 | J19: 1 | K19: 0 | L19: parsed
A20: 2026-01-07 | B20: Manatee Creek - Nori.csv | C20: Nori | E20: E | F20: ? | G20: 100% ABB | H20: 100% Wiltshire Horn | I20: 100 | J20: 0 | K20: 0 | L20: parsed
A21: 2026-01-07 | B21: Manatee Creek - OAV 2222(e).csv | C21: OAV 2222 | I21: 100 | J21: 1 | K21: 0 | L21: parsed
A22: 2026-01-07 | B22: Manatee Creek - Little Daisy(e).csv | F22: 3-23-23 | G22: Dodge | H22: Daisy | I22: 99.975 | J22: 0 | K22: 0 | L22: parsed
A23: 2026-01-07 | B23: Manatee Creek - 2022 30 day weights.csv | L23: SKIPPED: No (Name,Breed) header found
A24: 2026-01-07 | B24: Manatee Creek - Costs.csv | L24: SKIPPED: No (Name,Breed) header found

Sheet START_HERE
A1: Sheep Breeding Database (Template)
A3: Purpose
A4: Track animals, pedigrees, performance, parasite resilience, and hair/meat traits — then generate a safe, optimized mating plan (low inbreeding + lambing safety).
A6: How to use (recommended workflow)
A7: 1) Fill ANIMALS (one row per sheep). Use your own permanent AnimalID even if tags are missing.
A8: 2) Fill BREED_MIX using non‑zero breed %s (the superset list lives in BREED_SUPERSET).
A9: 3) Enter PERFORMANCE records (FAMACHA, FEC, DEWORM events, weights, shedding scores, etc.).
A10: 4) Optional: Enter MEDICAL events.
A11: 5) Set weights & safety rules in WEIGHTS_&_RULES (trait weights, inbreeding max, ewe‑lamb restrictions).
A12: 6) Review INDEX and PEN_STATS (auto-calculated).
A13: 7) Build your breeding assignments in MATING_PLAN. Paste pairwise relatedness/F_offspring in RELATIONSHIPS if available.
A15: Color legend
A16: Blue text | B16: Inputs you type/change
A17: Black text | B17: Formulas / calculated
A18: Light red fill | B18: Fails a safety rule (e.g., inbreeding cap, required fields missing)
A19: Light yellow fill | B19: Needs attention / missing data (not fatal)

Sheet IMPORT_LOG
A1: Imported On | B1: File | C1: Parsed Name | D1: Tag | E1: Sex | F1: DOB | G1: Sire | H1: Dam | I1: BreedMix Sum | J1: Famacha Rows | K1: FEC Rows | L1: Warnings
A2: 2026-01-06 | B2: Manatee Creek - 2241 (e).csv | C2: 2241 | D2: 2241 | I2: 100 | J2: 1 | K2: 0
A3: 2026-01-06 | B3: Manatee Creek - Buck (Kat x Awassi).csv | C3: Kat x awassi | I3: 100 | J3: 0 | K3: 0
A4: 2026-01-06 | B4: Manatee Creek - OAV 2223 (r) (Kelsier).csv | C4: Oav 2223 | E4: R | F4: 12-21-22 | I4: 100 | J4: 0 | K4: 9
A5: 2026-01-06 | B5: Manatee Creek - Broken Tail.csv | C5: Broken Tail | E5: E | G5: Sir Loin | H5: Half Tail | I5: 93.75 | J5: 0 | K5: 0
A6: 2026-01-06 | B6: Manatee Creek - GG (Gentle Giant).csv | C6: Fl51870 - 0502 (Pen 1-2) | E6: 0 | I6: 100 | J6: 0 | K6: 0
A7: 2026-01-06 | B7: Manatee Creek - OAV 2222(e).csv | C7: OAV 2222 | I7: 100 | J7: 0 | K7: 0
A8: 2026-01-06 | B8: Manatee Creek - Serendipity.csv | C8: Serendipity | D8: 30 | G8: Sir Loin | H8: Shaggy | I8: 100 | J8: 1 | K8: 0
A9: 2026-01-06 | B9: Manatee Creek - Nori.csv | C9: Nori | E9: E | F9: ? | G9: 100% ABB | H9: 100% Wiltshire Horn | I9: 100 | J9: 0 | K9: 0
A10: 2026-01-06 | B10: Manatee Creek - Elsie (E).csv | C10: Elsie | E10: E | F10: 2-8-22 | G10: Well Done | H10: Halftail | I10: 100 | J10: 2 | K10: 0
A11: 2026-01-06 | B11: Manatee Creek - Little Daisy(e).csv | F11: 3-23-23 | G11: Dodge | H11: Daisy | I11: 99.975 | J11: 0 | K11: 0

Sheet LIVING_ROSTER
A1: As Of | B1: Pen | C1: Group | D1: Display Name | E1: Tag/ID | F1: Sex | G1: Notes | H1: Needs Review?
A2: 2026-01-06 | B2: Pen 1 | C2: Ram | D2: 00110 | E2: 00110 | F2: R | G2: orange tag
A3: 2026-01-06 | B3: Pen 1 | C3: Ram | D3: Twin ram (brown & white) | F3: R | G3: no ID given | H3: missing tag/ID
A4: 2026-01-06 | B4: Pen 1 | C4: Ram | D4: Twin ram (black & white) | F4: R | G4: no ID given | H4: missing tag/ID
A5: 2026-01-06 | B5: Pen 1 | C5: Ewe | D5: 003 | E5: 003 | F5: E | G5: hair
A6: 2026-01-06 | B6: Pen 1 | C6: Ewe | D6: Azure | E6: 20 | F6: E | G6: also labeled Azure (20)
A7: 2026-01-06 | B7: Pen 1 | C7: Ewe | D7: 0044 | E7: 0044 | F7: E | G7: fluffy
A8: 2026-01-06 | B8: Pen 1 | C8: Ewe | D8: Charlie's ewe 2 | F8: E | G8: name-based ID needed | H8: missing tag/ID; assign house ID
A9: 2026-01-06 | B9: Pen 1 | C9: Ram lamb | D9: Ram lamb (brown & white) | F9: R | G9: no ID given | H9: missing tag/ID
A10: 2026-01-06 | B10: Pen 2 | C10: Ram | D10: Jerk Face | F10: R | G10: no tag | H10: missing tag/ID
A11: 2026-01-06 | B11: Pen 2 | C11: Ewe | D11: 0053 | E11: 0053 | F11: E | G11: hair
A12: 2026-01-06 | B12: Pen 2 | C12: Ewe | D12: 114 | E12: 114 | F12: E | G12: fawn; sister to 00110
A13: 2026-01-06 | B13: Pen 3 | C13: Ram | D13: Merrie | E13: 00016 | F13: R | G13: also referenced as Merrie (00016)
A14: 2026-01-06 | B14: Pen 3 | C14: Ram | D14: Charlie | F14: R | G14: no tag | H14: missing tag/ID
A15: 2026-01-06 | B15: Pen 3 | C15: Ewe | D15: Nori | E15: 0029 | F15: E | G15: tag 0029
A16: 2026-01-06 | B16: Pen 3 | C16: Ewe | D16: Broken Tail | F16: E | G16: tag lost | H16: missing tag/ID
A17: 2026-01-06 | B17: Pen 3 | C17: Ewe lamb | D17: Ewe lamb (Broken Tail x Charlie) #1 | F17: E | G17: twin | H17: missing tag/ID
A18: 2026-01-06 | B18: Pen 3 | C18: Ewe lamb | D18: Ewe lamb (Broken Tail x Charlie) #2 | F18: E | G18: twin | H18: missing tag/ID
A19: 2026-01-06 | B19: Pen 3 | C19: Ewe | D19: Charlie's ewe | F19: E | G19: name-based ID needed | H19: missing tag/ID; assign house ID
A20: 2026-01-06 | B20: Pen 3 | C20: Ewe lamb | D20: Ewe lamb (unidentified) | F20: E | G20: no ID given | H20: missing tag/ID
A21: 2026-01-06 | B21: Pen 4 | C21: Ewe | D21: 0023 | E21: 0023 | F21: E
A22: 2026-01-06 | B22: Pen 4 | C22: Ewe | D22: 0011 | E22: 0011 | F22: E | G22: wooly
A23: 2026-01-06 | B23: Pen 4 | C23: Ewe | D23: Gigi | F23: E | G23: no tag | H23: missing tag/ID
A24: 2026-01-06 | B24: Pen 4 | C24: Ewe | D24: Fms daughter | F24: E | G24: lost tag | H24: missing tag/ID
A25: 2026-01-06 | B25: Pen 4 | C25: Ewe | D25: Serendipity | F25: E | G25: no tag | H25: missing tag/ID
A26: 2026-01-06 | B26: Pen 4 | C26: Ram lamb | D26: Ram lamb (white) | F26: R | G26: no ID given | H26: missing tag/ID
A27: 2026-01-06 | B27: Pen 4 | C27: Ewe lamb | D27: Ewe lamb (black) | F27: E | G27: no ID given | H27: missing tag/ID
A28: 2026-01-06 | B28: Pen 4 | C28: Ewe | D28: 0051 | E28: 0051 | F28: E
A29: 2026-01-06 | B29: Pen 5 | C29: Ram | D29: 113 | E29: 113 | F29: R
A30: 2026-01-06 | B30: Pen 5 | C30: Ewe | D30: 02 | E30: 02 | F30: E
A31: 2026-01-06 | B31: Pen 5 | C31: Ewe | D31: 31 | E31: 31 | F31: E
A32: 2026-01-06 | B32: Pen 5 | C32: Unknown | D32: No-tag wooly fawn long-ears | G32: sex not stated | H32: missing tag/ID; missing sex
A33: 2026-01-06 | B33: Pen 6 | C33: Ram | D33: Mc08 | F33: R | G33: no tag in list | H33: missing tag/ID
A34: 2026-01-06 | B34: Pen 6 | C34: Ewe | D34: Elsie | F34: E | G34: no tag; recently triplets | H34: missing tag/ID
A35: 2026-01-06 | B35: Pen 6 | C35: Ewe lamb | D35: Ewe lamb (Elsie) white #1 | F35: E | G35: triplets 2026-01-06 | H35: missing tag/ID
A36: 2026-01-06 | B36: Pen 6 | C36: Ewe lamb | D36: Ewe lamb (Elsie) white #2 | F36: E | G36: triplets 2026-01-06 | H36: missing tag/ID
A37: 2026-01-06 | B37: Pen 6 | C37: Ram lamb | D37: Ram lamb (Elsie) black | F37: R | G37: triplets 2026-01-06 | H37: missing tag/ID
A38: 2026-01-06 | B38: Pen 6 | C38: Ewe | D38: 2139 | E38: 2139 | F38: E | G38: fat tail
A39: 2026-01-06 | B39: Pen 6 | C39: Ewe | D39: 0056 | E39: 0056 | F39: E | G39: fat tail
A40: 2026-01-06 | B40: Pen 6 | C40: Ewe | D40: 0055 | E40: 0055 | F40: E | G40: fat tail
...

Sheet ANIMALS
A1: AnimalID* | B1: Display Name | C1: Tag # | D1: Sex (E/R/W) | E1: DOB | F1: BirthYear | G1: AgeClass | H1: Pen/Group | I1: Status | J1: SireID | K1: DamID | L1: Received From | M1: Date Acquired | N1: Date Removed | O1: % Hair (calc) | P1: Expected wt (EWE, lb) (calc) | Q1: Expected wt (RAM, lb) (calc) | R1: Primary Breed (calc) | S1: Pedigree completeness (calc) | T1: Notes
A2: TAG_00110 | B2: 00110 | C2: 00110 | D2: R | F2: =IF($E2="","",YEAR($E2)) | G2: =IF($E2="","",IF(('WEIGHTS_&_RULES'!$B$3-$E2)<365,"Lamb",IF(('WEIGHTS_&_RULES'!$B$3-$E2)<730,"Yearling","Adult"))) | H2: Pen 1 | I2: Active | O2: =IFERROR(VLOOKUP($A2,BREED_MIX!$A$2:$AB$61,2,FALSE),"") | P2: =IFERROR(VLOOKUP($A2,BREED_MIX!$A$2:$AB$61,25,FALSE),"") | Q2: =IFERROR(VLOOKUP($A2,BREED_MIX!$A$2:$AB$61,26,FALSE),"") | R2: =IFERROR(VLOOKUP($A2,BREED_MIX!$A$2:$AB$61,27,FALSE),"") | S2: =IF($A2="","",IF(AND($J2<>"",$K2<>""),2,IF(OR($J2<>"",$K2<>""),1,0))) | T2: orange tag
A3: P1_TWIN_RAM_BROWNWHITE | B3: Twin ram (brown & white) | D3: R | F3: =IF($E3="","",YEAR($E3)) | G3: =IF($E3="","",IF(('WEIGHTS_&_RULES'!$B$3-$E3)<365,"Lamb",IF(('WEIGHTS_&_RULES'!$B$3-$E3)<730,"Yearling","Adult"))) | H3: Pen 1 | I3: Active | O3: =IFERROR(VLOOKUP($A3,BREED_MIX!$A$2:$AB$61,2,FALSE),"") | P3: =IFERROR(VLOOKUP($A3,BREED_MIX!$A$2:$AB$61,25,FALSE),"") | Q3: =IFERROR(VLOOKUP($A3,BREED_MIX!$A$2:$AB$61,26,FALSE),"") | R3: =IFERROR(VLOOKUP($A3,BREED_MIX!$A$2:$AB$61,27,FALSE),"") | S3: =IF($A3="","",IF(AND($J3<>"",$K3<>""),2,IF(OR($J3<>"",$K3<>""),1,0))) | T3: no ID
A4: P1_TWIN_RAM_BLACKWHITE | B4: Twin ram (black & white) | D4: R | F4: =IF($E4="","",YEAR($E4)) | G4: =IF($E4="","",IF(('WEIGHTS_&_RULES'!$B$3-$E4)<365,"Lamb",IF(('WEIGHTS_&_RULES'!$B$3-$E4)<730,"Yearling","Adult"))) | H4: Pen 1 | I4: Active | O4: =IFERROR(VLOOKUP($A4,BREED_MIX!$A$2:$AB$61,2,FALSE),"") | P4: =IFERROR(VLOOKUP($A4,BREED_MIX!$A$2:$AB$61,25,FALSE),"") | Q4: =IFERROR(VLOOKUP($A4,BREED_MIX!$A$2:$AB$61,26,FALSE),"") | R4: =IFERROR(VLOOKUP($A4,BREED_MIX!$A$2:$AB$61,27,FALSE),"") | S4: =IF($A4="","",IF(AND($J4<>"",$K4<>""),2,IF(OR($J4<>"",$K4<>""),1,0))) | T4: no ID
A5: TAG_0003 | B5: 003 | C5: 003 | D5: E | F5: =IF($E5="","",YEAR($E5)) | G5: =IF($E5="","",IF(('WEIGHTS_&_RULES'!$B$3-$E5)<365,"Lamb",IF(('WEIGHTS_&_RULES'!$B$3-$E5)<730,"Yearling","Adult"))) | H5: Pen 1 | I5: Active | O5: =IFERROR(VLOOKUP($A5,BREED_MIX!$A$2:$AB$61,2,FALSE),"") | P5: =IFERROR(VLOOKUP($A5,BREED_MIX!$A$2:$AB$61,25,FALSE),"") | Q5: =IFERROR(VLOOKUP($A5,BREED_MIX!$A$2:$AB$61,26,FALSE),"") | R5: =IFERROR(VLOOKUP($A5,BREED_MIX!$A$2:$AB$61,27,FALSE),"") | S5: =IF($A5="","",IF(AND($J5<>"",$K5<>""),2,IF(OR($J5<>"",$K5<>""),1,0))) | T5: hair
A6: AZURE_0020 | B6: Azure | C6: 20 | D6: E | F6: =IF($E6="","",YEAR($E6)) | G6: =IF($E6="","",IF(('WEIGHTS_&_RULES'!$B$3-$E6)<365,"Lamb",IF(('WEIGHTS_&_RULES'!$B$3-$E6)<730,"Yearling","Adult"))) | H6: Pen 1 | I6: Active | O6: =IFERROR(VLOOKUP($A6,BREED_MIX!$A$2:$AB$61,2,FALSE),"") | P6: =IFERROR(VLOOKUP($A6,BREED_MIX!$A$2:$AB$61,25,FALSE),"") | Q6: =IFERROR(VLOOKUP($A6,BREED_MIX!$A$2:$AB$61,26,FALSE),"") | R6: =IFERROR(VLOOKUP($A6,BREED_MIX!$A$2:$AB$61,27,FALSE),"") | S6: =IF($A6="","",IF(AND($J6<>"",$K6<>""),2,IF(OR($J6<>"",$K6<>""),1,0))) | T6: Azure (20)
A7: TAG_0044 | B7: 0044 | C7: 0044 | D7: E | F7: =IF($E7="","",YEAR($E7)) | G7: =IF($E7="","",IF(('WEIGHTS_&_RULES'!$B$3-$E7)<365,"Lamb",IF(('WEIGHTS_&_RULES'!$B$3-$E7)<730,"Yearling","Adult"))) | H7: Pen 1 | I7: Active | O7: =IFERROR(VLOOKUP($A7,BREED_MIX!$A$2:$AB$61,2,FALSE),"") | P7: =IFERROR(VLOOKUP($A7,BREED_MIX!$A$2:$AB$61,25,FALSE),"") | Q7: =IFERROR(VLOOKUP($A7,BREED_MIX!$A$2:$AB$61,26,FALSE),"") | R7: =IFERROR(VLOOKUP($A7,BREED_MIX!$A$2:$AB$61,27,FALSE),"") | S7: =IF($A7="","",IF(AND($J7<>"",$K7<>""),2,IF(OR($J7<>"",$K7<>""),1,0))) | T7: fluffy
A8: CHARLIES_EWE_2 | B8: Charlie's ewe 2 | D8: E | F8: =IF($E8="","",YEAR($E8)) | G8: =IF($E8="","",IF(('WEIGHTS_&_RULES'!$B$3-$E8)<365,"Lamb",IF(('WEIGHTS_&_RULES'!$B$3-$E8)<730,"Yearling","Adult"))) | H8: Pen 1 | I8: Active | O8: =IFERROR(VLOOKUP($A8,BREED_MIX!$A$2:$AB$61,2,FALSE),"") | P8: =IFERROR(VLOOKUP($A8,BREED_MIX!$A$2:$AB$61,25,FALSE),"") | Q8: =IFERROR(VLOOKUP($A8,BREED_MIX!$A$2:$AB$61,26,FALSE),"") | R8: =IFERROR(VLOOKUP($A8,BREED_MIX!$A$2:$AB$61,27,FALSE),"") | S8: =IF($A8="","",IF(AND($J8<>"",$K8<>""),2,IF(OR($J8<>"",$K8<>""),1,0))) | T8: no tag
A9: P1_RAM_LAMB_BROWNWHITE_01 | B9: Ram lamb (brown & white) | D9: R | F9: =IF($E9="","",YEAR($E9)) | G9: =IF($E9="","",IF(('WEIGHTS_&_RULES'!$B$3-$E9)<365,"Lamb",IF(('WEIGHTS_&_RULES'!$B$3-$E9)<730,"Yearling","Adult"))) | H9: Pen 1 | I9: Active | O9: =IFERROR(VLOOKUP($A9,BREED_MIX!$A$2:$AB$61,2,FALSE),"") | P9: =IFERROR(VLOOKUP($A9,BREED_MIX!$A$2:$AB$61,25,FALSE),"") | Q9: =IFERROR(VLOOKUP($A9,BREED_MIX!$A$2:$AB$61,26,FALSE),"") | R9: =IFERROR(VLOOKUP($A9,BREED_MIX!$A$2:$AB$61,27,FALSE),"") | S9: =IF($A9="","",IF(AND($J9<>"",$K9<>""),2,IF(OR($J9<>"",$K9<>""),1,0))) | T9: no ID
A10: JERK_FACE | B10: Jerk Face | D10: R | F10: =IF($E10="","",YEAR($E10)) | G10: =IF($E10="","",IF(('WEIGHTS_&_RULES'!$B$3-$E10)<365,"Lamb",IF(('WEIGHTS_&_RULES'!$B$3-$E10)<730,"Yearling","Adult"))) | H10: Pen 2 | I10: Active | O10: =IFERROR(VLOOKUP($A10,BREED_MIX!$A$2:$AB$61,2,FALSE),"") | P10: =IFERROR(VLOOKUP($A10,BREED_MIX!$A$2:$AB$61,25,FALSE),"") | Q10: =IFERROR(VLOOKUP($A10,BREED_MIX!$A$2:$AB$61,26,FALSE),"") | R10: =IFERROR(VLOOKUP($A10,BREED_MIX!$A$2:$AB$61,27,FALSE),"") | S10: =IF($A10="","",IF(AND($J10<>"",$K10<>""),2,IF(OR($J10<>"",$K10<>""),1,0))) | T10: no tag
A11: TAG_0053 | B11: 0053 | C11: 0053 | D11: E | F11: =IF($E11="","",YEAR($E11)) | G11: =IF($E11="","",IF(('WEIGHTS_&_RULES'!$B$3-$E11)<365,"Lamb",IF(('WEIGHTS_&_RULES'!$B$3-$E11)<730,"Yearling","Adult"))) | H11: Pen 2 | I11: Active | O11: =IFERROR(VLOOKUP($A11,BREED_MIX!$A$2:$AB$61,2,FALSE),"") | P11: =IFERROR(VLOOKUP($A11,BREED_MIX!$A$2:$AB$61,25,FALSE),"") | Q11: =IFERROR(VLOOKUP($A11,BREED_MIX!$A$2:$AB$61,26,FALSE),"") | R11: =IFERROR(VLOOKUP($A11,BREED_MIX!$A$2:$AB$61,27,FALSE),"") | S11: =IF($A11="","",IF(AND($J11<>"",$K11<>""),2,IF(OR($J11<>"",$K11<>""),1,0))) | T11: hair
A12: TAG_0114 | B12: 114 | C12: 114 | D12: E | F12: =IF($E12="","",YEAR($E12)) | G12: =IF($E12="","",IF(('WEIGHTS_&_RULES'!$B$3-$E12)<365,"Lamb",IF(('WEIGHTS_&_RULES'!$B$3-$E12)<730,"Yearling","Adult"))) | H12: Pen 2 | I12: Active | O12: =IFERROR(VLOOKUP($A12,BREED_MIX!$A$2:$AB$61,2,FALSE),"") | P12: =IFERROR(VLOOKUP($A12,BREED_MIX!$A$2:$AB$61,25,FALSE),"") | Q12: =IFERROR(VLOOKUP($A12,BREED_MIX!$A$2:$AB$61,26,FALSE),"") | R12: =IFERROR(VLOOKUP($A12,BREED_MIX!$A$2:$AB$61,27,FALSE),"") | S12: =IF($A12="","",IF(AND($J12<>"",$K12<>""),2,IF(OR($J12<>"",$K12<>""),1,0))) | T12: fawn; sister to 00110
A13: MERRIE | B13: Merrie | C13: 00016 | D13: R | F13: =IF($E13="","",YEAR($E13)) | G13: =IF($E13="","",IF(('WEIGHTS_&_RULES'!$B$3-$E13)<365,"Lamb",IF(('WEIGHTS_&_RULES'!$B$3-$E13)<730,"Yearling","Adult"))) | H13: Pen 3 | I13: Active | J13: SMORE | K13: HALFTAIL | O13: =IFERROR(VLOOKUP($A13,BREED_MIX!$A$2:$AB$61,2,FALSE),"") | P13: =IFERROR(VLOOKUP($A13,BREED_MIX!$A$2:$AB$61,25,FALSE),"") | Q13: =IFERROR(VLOOKUP($A13,BREED_MIX!$A$2:$AB$61,26,FALSE),"") | R13: =IFERROR(VLOOKUP($A13,BREED_MIX!$A$2:$AB$61,27,FALSE),"") | S13: =IF($A13="","",IF(AND($J13<>"",$K13<>""),2,IF(OR($J13<>"",$K13<>""),1,0)))
A14: CHARLIE | B14: Charlie | D14: R | F14: =IF($E14="","",YEAR($E14)) | G14: =IF($E14="","",IF(('WEIGHTS_&_RULES'!$B$3-$E14)<365,"Lamb",IF(('WEIGHTS_&_RULES'!$B$3-$E14)<730,"Yearling","Adult"))) | H14: Pen 3 | I14: Active | O14: =IFERROR(VLOOKUP($A14,BREED_MIX!$A$2:$AB$61,2,FALSE),"") | P14: =IFERROR(VLOOKUP($A14,BREED_MIX!$A$2:$AB$61,25,FALSE),"") | Q14: =IFERROR(VLOOKUP($A14,BREED_MIX!$A$2:$AB$61,26,FALSE),"") | R14: =IFERROR(VLOOKUP($A14,BREED_MIX!$A$2:$AB$61,27,FALSE),"") | S14: =IF($A14="","",IF(AND($J14<>"",$K14<>""),2,IF(OR($J14<>"",$K14<>""),1,0))) | T14: no tag
A15: NORI_0029 | B15: Nori | C15: 0029 | D15: E | E15: ? | F15: =IF($E15="","",YEAR($E15)) | G15: =IF($E15="","",IF(('WEIGHTS_&_RULES'!$B$3-$E15)<365,"Lamb",IF(('WEIGHTS_&_RULES'!$B$3-$E15)<730,"Yearling","Adult"))) | H15: Pen 3 | I15: Active | J15: 100% ABB | K15: 100% Wiltshire Horn | O15: =IFERROR(VLOOKUP($A15,BREED_MIX!$A$2:$AB$61,2,FALSE),"") | P15: =IFERROR(VLOOKUP($A15,BREED_MIX!$A$2:$AB$61,25,FALSE),"") | Q15: =IFERROR(VLOOKUP($A15,BREED_MIX!$A$2:$AB$61,26,FALSE),"") | R15: =IFERROR(VLOOKUP($A15,BREED_MIX!$A$2:$AB$61,27,FALSE),"") | S15: =IF($A15="","",IF(AND($J15<>"",$K15<>""),2,IF(OR($J15<>"",$K15<>""),1,0))) | T15: Nori (0029)
A16: BROKEN_TAIL | B16: Broken Tail | D16: E | F16: =IF($E16="","",YEAR($E16)) | G16: =IF($E16="","",IF(('WEIGHTS_&_RULES'!$B$3-$E16)<365,"Lamb",IF(('WEIGHTS_&_RULES'!$B$3-$E16)<730,"Yearling","Adult"))) | H16: Pen 3 | I16: Active | J16: SIRLOIN | K16: HALFTAIL | O16: =IFERROR(VLOOKUP($A16,BREED_MIX!$A$2:$AB$61,2,FALSE),"") | P16: =IFERROR(VLOOKUP($A16,BREED_MIX!$A$2:$AB$61,25,FALSE),"") | Q16: =IFERROR(VLOOKUP($A16,BREED_MIX!$A$2:$AB$61,26,FALSE),"") | R16: =IFERROR(VLOOKUP($A16,BREED_MIX!$A$2:$AB$61,27,FALSE),"") | S16: =IF($A16="","",IF(AND($J16<>"",$K16<>""),2,IF(OR($J16<>"",$K16<>""),1,0))) | T16: tag lost
A17: BTXC_TWIN_EWE_1 | B17: BT x Charlie twin ewe lamb #1 | D17: E | F17: =IF($E17="","",YEAR($E17)) | G17: =IF($E17="","",IF(('WEIGHTS_&_RULES'!$B$3-$E17)<365,"Lamb",IF(('WEIGHTS_&_RULES'!$B$3-$E17)<730,"Yearling","Adult"))) | H17: Pen 3 | I17: Inactive (not on 2026-01-06 living roster) | J17: CHARLIE | K17: BROKEN_TAIL | O17: =IFERROR(VLOOKUP($A17,BREED_MIX!$A$2:$AB$61,2,FALSE),"") | P17: =IFERROR(VLOOKUP($A17,BREED_MIX!$A$2:$AB$61,25,FALSE),"") | Q17: =IFERROR(VLOOKUP($A17,BREED_MIX!$A$2:$AB$61,26,FALSE),"") | R17: =IFERROR(VLOOKUP($A17,BREED_MIX!$A$2:$AB$61,27,FALSE),"") | S17: =IF($A17="","",IF(AND($J17<>"",$K17<>""),2,IF(OR($J17<>"",$K17<>""),1,0))) | T17: Broken Tail x Charlie; twin
A18: BTXC_TWIN_EWE_2 | B18: BT x Charlie twin ewe lamb #2 | D18: E | F18: =IF($E18="","",YEAR($E18)) | G18: =IF($E18="","",IF(('WEIGHTS_&_RULES'!$B$3-$E18)<365,"Lamb",IF(('WEIGHTS_&_RULES'!$B$3-$E18)<730,"Yearling","Adult"))) | H18: Pen 3 | I18: Inactive (not on 2026-01-06 living roster) | J18: CHARLIE | K18: BROKEN_TAIL | O18: =IFERROR(VLOOKUP($A18,BREED_MIX!$A$2:$AB$61,2,FALSE),"") | P18: =IFERROR(VLOOKUP($A18,BREED_MIX!$A$2:$AB$61,25,FALSE),"") | Q18: =IFERROR(VLOOKUP($A18,BREED_MIX!$A$2:$AB$61,26,FALSE),"") | R18: =IFERROR(VLOOKUP($A18,BREED_MIX!$A$2:$AB$61,27,FALSE),"") | S18: =IF($A18="","",IF(AND($J18<>"",$K18<>""),2,IF(OR($J18<>"",$K18<>""),1,0))) | T18: Broken Tail x Charlie; twin
A19: CHARLIES_EWE_1 | B19: Charlie's ewe | D19: E | F19: =IF($E19="","",YEAR($E19)) | G19: =IF($E19="","",IF(('WEIGHTS_&_RULES'!$B$3-$E19)<365,"Lamb",IF(('WEIGHTS_&_RULES'!$B$3-$E19)<730,"Yearling","Adult"))) | H19: Pen 3 | I19: Active | O19: =IFERROR(VLOOKUP($A19,BREED_MIX!$A$2:$AB$61,2,FALSE),"") | P19: =IFERROR(VLOOKUP($A19,BREED_MIX!$A$2:$AB$61,25,FALSE),"") | Q19: =IFERROR(VLOOKUP($A19,BREED_MIX!$A$2:$AB$61,26,FALSE),"") | R19: =IFERROR(VLOOKUP($A19,BREED_MIX!$A$2:$AB$61,27,FALSE),"") | S19: =IF($A19="","",IF(AND($J19<>"",$K19<>""),2,IF(OR($J19<>"",$K19<>""),1,0))) | T19: no tag
A20: P3_EWE_LAMB_01 | B20: Ewe lamb (unknown) | D20: E | F20: =IF($E20="","",YEAR($E20)) | G20: =IF($E20="","",IF(('WEIGHTS_&_RULES'!$B$3-$E20)<365,"Lamb",IF(('WEIGHTS_&_RULES'!$B$3-$E20)<730,"Yearling","Adult"))) | H20: Pen 3 | I20: Inactive (not on 2026-01-06 living roster) | O20: =IFERROR(VLOOKUP($A20,BREED_MIX!$A$2:$AB$61,2,FALSE),"") | P20: =IFERROR(VLOOKUP($A20,BREED_MIX!$A$2:$AB$61,25,FALSE),"") | Q20: =IFERROR(VLOOKUP($A20,BREED_MIX!$A$2:$AB$61,26,FALSE),"") | R20: =IFERROR(VLOOKUP($A20,BREED_MIX!$A$2:$AB$61,27,FALSE),"") | S20: =IF($A20="","",IF(AND($J20<>"",$K20<>""),2,IF(OR($J20<>"",$K20<>""),1,0))) | T20: no tag
A21: TAG_0023 | B21: 0023 | C21: 0023 | D21: E | F21: =IF($E21="","",YEAR($E21)) | G21: =IF($E21="","",IF(('WEIGHTS_&_RULES'!$B$3-$E21)<365,"Lamb",IF(('WEIGHTS_&_RULES'!$B$3-$E21)<730,"Yearling","Adult"))) | H21: Pen 4 | I21: Active | O21: =IFERROR(VLOOKUP($A21,BREED_MIX!$A$2:$AB$61,2,FALSE),"") | P21: =IFERROR(VLOOKUP($A21,BREED_MIX!$A$2:$AB$61,25,FALSE),"") | Q21: =IFERROR(VLOOKUP($A21,BREED_MIX!$A$2:$AB$61,26,FALSE),"") | R21: =IFERROR(VLOOKUP($A21,BREED_MIX!$A$2:$AB$61,27,FALSE),"") | S21: =IF($A21="","",IF(AND($J21<>"",$K21<>""),2,IF(OR($J21<>"",$K21<>""),1,0)))
A22: TAG_0011 | B22: 0011 | C22: 0011 | D22: E | F22: =IF($E22="","",YEAR($E22)) | G22: =IF($E22="","",IF(('WEIGHTS_&_RULES'!$B$3-$E22)<365,"Lamb",IF(('WEIGHTS_&_RULES'!$B$3-$E22)<730,"Yearling","Adult"))) | H22: Pen 4 | I22: Active | O22: =IFERROR(VLOOKUP($A22,BREED_MIX!$A$2:$AB$61,2,FALSE),"") | P22: =IFERROR(VLOOKUP($A22,BREED_MIX!$A$2:$AB$61,25,FALSE),"") | Q22: =IFERROR(VLOOKUP($A22,BREED_MIX!$A$2:$AB$61,26,FALSE),"") | R22: =IFERROR(VLOOKUP($A22,BREED_MIX!$A$2:$AB$61,27,FALSE),"") | S22: =IF($A22="","",IF(AND($J22<>"",$K22<>""),2,IF(OR($J22<>"",$K22<>""),1,0))) | T22: wooly
A23: GIGI | B23: Gigi | D23: E | F23: =IF($E23="","",YEAR($E23)) | G23: =IF($E23="","",IF(('WEIGHTS_&_RULES'!$B$3-$E23)<365,"Lamb",IF(('WEIGHTS_&_RULES'!$B$3-$E23)<730,"Yearling","Adult"))) | H23: Pen 4 | I23: Active | O23: =IFERROR(VLOOKUP($A23,BREED_MIX!$A$2:$AB$61,2,FALSE),"") | P23: =IFERROR(VLOOKUP($A23,BREED_MIX!$A$2:$AB$61,25,FALSE),"") | Q23: =IFERROR(VLOOKUP($A23,BREED_MIX!$A$2:$AB$61,26,FALSE),"") | R23: =IFERROR(VLOOKUP($A23,BREED_MIX!$A$2:$AB$61,27,FALSE),"") | S23: =IF($A23="","",IF(AND($J23<>"",$K23<>""),2,IF(OR($J23<>"",$K23<>""),1,0))) | T23: no tag
A24: FMS_DAUGHTER | B24: Fms daughter | D24: E | F24: =IF($E24="","",YEAR($E24)) | G24: =IF($E24="","",IF(('WEIGHTS_&_RULES'!$B$3-$E24)<365,"Lamb",IF(('WEIGHTS_&_RULES'!$B$3-$E24)<730,"Yearling","Adult"))) | H24: Pen 4 | I24: Active | O24: =IFERROR(VLOOKUP($A24,BREED_MIX!$A$2:$AB$61,2,FALSE),"") | P24: =IFERROR(VLOOKUP($A24,BREED_MIX!$A$2:$AB$61,25,FALSE),"") | Q24: =IFERROR(VLOOKUP($A24,BREED_MIX!$A$2:$AB$61,26,FALSE),"") | R24: =IFERROR(VLOOKUP($A24,BREED_MIX!$A$2:$AB$61,27,FALSE),"") | S24: =IF($A24="","",IF(AND($J24<>"",$K24<>""),2,IF(OR($J24<>"",$K24<>""),1,0))) | T24: lost tag
A25: SERENDIPITY | B25: Serendipity | C25: 30 | D25: E | E25: 3-25-22 | F25: =IF($E25="","",YEAR($E25)) | G25: =IF($E25="","",IF(('WEIGHTS_&_RULES'!$B$3-$E25)<365,"Lamb",IF(('WEIGHTS_&_RULES'!$B$3-$E25)<730,"Yearling","Adult"))) | H25: Pen 4 | I25: Active | J25: Sirloin | K25: SHAGGY | O25: =IFERROR(VLOOKUP($A25,BREED_MIX!$A$2:$AB$61,2,FALSE),"") | P25: =IFERROR(VLOOKUP($A25,BREED_MIX!$A$2:$AB$61,25,FALSE),"") | Q25: =IFERROR(VLOOKUP($A25,BREED_MIX!$A$2:$AB$61,26,FALSE),"") | R25: =IFERROR(VLOOKUP($A25,BREED_MIX!$A$2:$AB$61,27,FALSE),"") | S25: =IF($A25="","",IF(AND($J25<>"",$K25<>""),2,IF(OR($J25<>"",$K25<>""),1,0))) | T25: no tag
A26: P4_RAM_LAMB_WHITE_01 | B26: Ram lamb (white) | D26: R | F26: =IF($E26="","",YEAR($E26)) | G26: =IF($E26="","",IF(('WEIGHTS_&_RULES'!$B$3-$E26)<365,"Lamb",IF(('WEIGHTS_&_RULES'!$B$3-$E26)<730,"Yearling","Adult"))) | H26: Pen 4 | I26: Active | O26: =IFERROR(VLOOKUP($A26,BREED_MIX!$A$2:$AB$61,2,FALSE),"") | P26: =IFERROR(VLOOKUP($A26,BREED_MIX!$A$2:$AB$61,25,FALSE),"") | Q26: =IFERROR(VLOOKUP($A26,BREED_MIX!$A$2:$AB$61,26,FALSE),"") | R26: =IFERROR(VLOOKUP($A26,BREED_MIX!$A$2:$AB$61,27,FALSE),"") | S26: =IF($A26="","",IF(AND($J26<>"",$K26<>""),2,IF(OR($J26<>"",$K26<>""),1,0))) | T26: no ID
A27: P4_EWE_LAMB_BLACK_01 | B27: Ewe lamb (black) | D27: E | F27: =IF($E27="","",YEAR($E27)) | G27: =IF($E27="","",IF(('WEIGHTS_&_RULES'!$B$3-$E27)<365,"Lamb",IF(('WEIGHTS_&_RULES'!$B$3-$E27)<730,"Yearling","Adult"))) | H27: Pen 4 | I27: Active | O27: =IFERROR(VLOOKUP($A27,BREED_MIX!$A$2:$AB$61,2,FALSE),"") | P27: =IFERROR(VLOOKUP($A27,BREED_MIX!$A$2:$AB$61,25,FALSE),"") | Q27: =IFERROR(VLOOKUP($A27,BREED_MIX!$A$2:$AB$61,26,FALSE),"") | R27: =IFERROR(VLOOKUP($A27,BREED_MIX!$A$2:$AB$61,27,FALSE),"") | S27: =IF($A27="","",IF(AND($J27<>"",$K27<>""),2,IF(OR($J27<>"",$K27<>""),1,0))) | T27: no ID
A28: TAG_0051 | B28: 0051 | C28: 0051 | D28: E | F28: =IF($E28="","",YEAR($E28)) | G28: =IF($E28="","",IF(('WEIGHTS_&_RULES'!$B$3-$E28)<365,"Lamb",IF(('WEIGHTS_&_RULES'!$B$3-$E28)<730,"Yearling","Adult"))) | H28: Pen 4 | I28: Active | O28: =IFERROR(VLOOKUP($A28,BREED_MIX!$A$2:$AB$61,2,FALSE),"") | P28: =IFERROR(VLOOKUP($A28,BREED_MIX!$A$2:$AB$61,25,FALSE),"") | Q28: =IFERROR(VLOOKUP($A28,BREED_MIX!$A$2:$AB$61,26,FALSE),"") | R28: =IFERROR(VLOOKUP($A28,BREED_MIX!$A$2:$AB$61,27,FALSE),"") | S28: =IF($A28="","",IF(AND($J28<>"",$K28<>""),2,IF(OR($J28<>"",$K28<>""),1,0)))
A29: TAG_0113 | B29: 113 | C29: 113 | D29: R | F29: =IF($E29="","",YEAR($E29)) | G29: =IF($E29="","",IF(('WEIGHTS_&_RULES'!$B$3-$E29)<365,"Lamb",IF(('WEIGHTS_&_RULES'!$B$3-$E29)<730,"Yearling","Adult"))) | H29: Pen 5 | I29: Active | O29: =IFERROR(VLOOKUP($A29,BREED_MIX!$A$2:$AB$61,2,FALSE),"") | P29: =IFERROR(VLOOKUP($A29,BREED_MIX!$A$2:$AB$61,25,FALSE),"") | Q29: =IFERROR(VLOOKUP($A29,BREED_MIX!$A$2:$AB$61,26,FALSE),"") | R29: =IFERROR(VLOOKUP($A29,BREED_MIX!$A$2:$AB$61,27,FALSE),"") | S29: =IF($A29="","",IF(AND($J29<>"",$K29<>""),2,IF(OR($J29<>"",$K29<>""),1,0)))
A30: TAG_0002 | B30: 02 | C30: 02 | D30: E | F30: =IF($E30="","",YEAR($E30)) | G30: =IF($E30="","",IF(('WEIGHTS_&_RULES'!$B$3-$E30)<365,"Lamb",IF(('WEIGHTS_&_RULES'!$B$3-$E30)<730,"Yearling","Adult"))) | H30: Pen 5 | I30: Active | O30: =IFERROR(VLOOKUP($A30,BREED_MIX!$A$2:$AB$61,2,FALSE),"") | P30: =IFERROR(VLOOKUP($A30,BREED_MIX!$A$2:$AB$61,25,FALSE),"") | Q30: =IFERROR(VLOOKUP($A30,BREED_MIX!$A$2:$AB$61,26,FALSE),"") | R30: =IFERROR(VLOOKUP($A30,BREED_MIX!$A$2:$AB$61,27,FALSE),"") | S30: =IF($A30="","",IF(AND($J30<>"",$K30<>""),2,IF(OR($J30<>"",$K30<>""),1,0)))
A31: TAG_0031 | B31: 31 | C31: 31 | D31: E | F31: =IF($E31="","",YEAR($E31)) | G31: =IF($E31="","",IF(('WEIGHTS_&_RULES'!$B$3-$E31)<365,"Lamb",IF(('WEIGHTS_&_RULES'!$B$3-$E31)<730,"Yearling","Adult"))) | H31: Pen 5 | I31: Active | O31: =IFERROR(VLOOKUP($A31,BREED_MIX!$A$2:$AB$61,2,FALSE),"") | P31: =IFERROR(VLOOKUP($A31,BREED_MIX!$A$2:$AB$61,25,FALSE),"") | Q31: =IFERROR(VLOOKUP($A31,BREED_MIX!$A$2:$AB$61,26,FALSE),"") | R31: =IFERROR(VLOOKUP($A31,BREED_MIX!$A$2:$AB$61,27,FALSE),"") | S31: =IF($A31="","",IF(AND($J31<>"",$K31<>""),2,IF(OR($J31<>"",$K31<>""),1,0)))
A32: P5_WOOLY_FAWN_LONGEARS_UNK | B32: (no tag) wooly fawn long ears | F32: =IF($E32="","",YEAR($E32)) | G32: =IF($E32="","",IF(('WEIGHTS_&_RULES'!$B$3-$E32)<365,"Lamb",IF(('WEIGHTS_&_RULES'!$B$3-$E32)<730,"Yearling","Adult"))) | H32: Pen 5 | I32: Inactive (not on 2026-01-06 living roster) | O32: =IFERROR(VLOOKUP($A32,BREED_MIX!$A$2:$AB$61,2,FALSE),"") | P32: =IFERROR(VLOOKUP($A32,BREED_MIX!$A$2:$AB$61,25,FALSE),"") | Q32: =IFERROR(VLOOKUP($A32,BREED_MIX!$A$2:$AB$61,26,FALSE),"") | R32: =IFERROR(VLOOKUP($A32,BREED_MIX!$A$2:$AB$61,27,FALSE),"") | S32: =IF($A32="","",IF(AND($J32<>"",$K32<>""),2,IF(OR($J32<>"",$K32<>""),1,0))) | T32: sex not stated
A33: MC08 | B33: Mc08 | C33: Mc08 | D33: R | F33: =IF($E33="","",YEAR($E33)) | G33: =IF($E33="","",IF(('WEIGHTS_&_RULES'!$B$3-$E33)<365,"Lamb",IF(('WEIGHTS_&_RULES'!$B$3-$E33)<730,"Yearling","Adult"))) | H33: Pen 6 | I33: Active | O33: =IFERROR(VLOOKUP($A33,BREED_MIX!$A$2:$AB$61,2,FALSE),"") | P33: =IFERROR(VLOOKUP($A33,BREED_MIX!$A$2:$AB$61,25,FALSE),"") | Q33: =IFERROR(VLOOKUP($A33,BREED_MIX!$A$2:$AB$61,26,FALSE),"") | R33: =IFERROR(VLOOKUP($A33,BREED_MIX!$A$2:$AB$61,27,FALSE),"") | S33: =IF($A33="","",IF(AND($J33<>"",$K33<>""),2,IF(OR($J33<>"",$K33<>""),1,0)))
A34: ELSIE | B34: Elsie | D34: E | E34: 2-8-22 | F34: =IF($E34="","",YEAR($E34)) | G34: =IF($E34="","",IF(('WEIGHTS_&_RULES'!$B$3-$E34)<365,"Lamb",IF(('WEIGHTS_&_RULES'!$B$3-$E34)<730,"Yearling","Adult"))) | H34: Pen 6 | I34: Active | J34: WELLDONE | K34: Halftail | O34: =IFERROR(VLOOKUP($A34,BREED_MIX!$A$2:$AB$61,2,FALSE),"") | P34: =IFERROR(VLOOKUP($A34,BREED_MIX!$A$2:$AB$61,25,FALSE),"") | Q34: =IFERROR(VLOOKUP($A34,BREED_MIX!$A$2:$AB$61,26,FALSE),"") | R34: =IFERROR(VLOOKUP($A34,BREED_MIX!$A$2:$AB$61,27,FALSE),"") | S34: =IF($A34="","",IF(AND($J34<>"",$K34<>""),2,IF(OR($J34<>"",$K34<>""),1,0))) | T34: tag lost (had tag 25 in records)
A35: ELSIE_2026_L1 | B35: Elsie triplet ewe lamb #1 (white) | D35: E | E35: 46028 | F35: =IF($E35="","",YEAR($E35)) | G35: =IF($E35="","",IF(('WEIGHTS_&_RULES'!$B$3-$E35)<365,"Lamb",IF(('WEIGHTS_&_RULES'!$B$3-$E35)<730,"Yearling","Adult"))) | H35: Pen 6 | I35: Inactive (not on 2026-01-06 living roster) | K35: ELSIE | O35: =IFERROR(VLOOKUP($A35,BREED_MIX!$A$2:$AB$61,2,FALSE),"") | P35: =IFERROR(VLOOKUP($A35,BREED_MIX!$A$2:$AB$61,25,FALSE),"") | Q35: =IFERROR(VLOOKUP($A35,BREED_MIX!$A$2:$AB$61,26,FALSE),"") | R35: =IFERROR(VLOOKUP($A35,BREED_MIX!$A$2:$AB$61,27,FALSE),"") | S35: =IF($A35="","",IF(AND($J35<>"",$K35<>""),2,IF(OR($J35<>"",$K35<>""),1,0))) | T35: born 2026-01-06
A36: ELSIE_2026_L2 | B36: Elsie triplet ewe lamb #2 (white) | D36: E | E36: 46028 | F36: =IF($E36="","",YEAR($E36)) | G36: =IF($E36="","",IF(('WEIGHTS_&_RULES'!$B$3-$E36)<365,"Lamb",IF(('WEIGHTS_&_RULES'!$B$3-$E36)<730,"Yearling","Adult"))) | H36: Pen 6 | I36: Inactive (not on 2026-01-06 living roster) | K36: ELSIE | O36: =IFERROR(VLOOKUP($A36,BREED_MIX!$A$2:$AB$61,2,FALSE),"") | P36: =IFERROR(VLOOKUP($A36,BREED_MIX!$A$2:$AB$61,25,FALSE),"") | Q36: =IFERROR(VLOOKUP($A36,BREED_MIX!$A$2:$AB$61,26,FALSE),"") | R36: =IFERROR(VLOOKUP($A36,BREED_MIX!$A$2:$AB$61,27,FALSE),"") | S36: =IF($A36="","",IF(AND($J36<>"",$K36<>""),2,IF(OR($J36<>"",$K36<>""),1,0))) | T36: born 2026-01-06
A37: ELSIE_2026_L3 | B37: Elsie triplet ram lamb (black) | D37: R | E37: 46028 | F37: =IF($E37="","",YEAR($E37)) | G37: =IF($E37="","",IF(('WEIGHTS_&_RULES'!$B$3-$E37)<365,"Lamb",IF(('WEIGHTS_&_RULES'!$B$3-$E37)<730,"Yearling","Adult"))) | H37: Pen 6 | I37: Inactive (not on 2026-01-06 living roster) | K37: ELSIE | O37: =IFERROR(VLOOKUP($A37,BREED_MIX!$A$2:$AB$61,2,FALSE),"") | P37: =IFERROR(VLOOKUP($A37,BREED_MIX!$A$2:$AB$61,25,FALSE),"") | Q37: =IFERROR(VLOOKUP($A37,BREED_MIX!$A$2:$AB$61,26,FALSE),"") | R37: =IFERROR(VLOOKUP($A37,BREED_MIX!$A$2:$AB$61,27,FALSE),"") | S37: =IF($A37="","",IF(AND($J37<>"",$K37<>""),2,IF(OR($J37<>"",$K37<>""),1,0))) | T37: born 2026-01-06
A38: TAG_2139 | B38: 2139 | C38: 2139 | D38: E | F38: =IF($E38="","",YEAR($E38)) | G38: =IF($E38="","",IF(('WEIGHTS_&_RULES'!$B$3-$E38)<365,"Lamb",IF(('WEIGHTS_&_RULES'!$B$3-$E38)<730,"Yearling","Adult"))) | H38: Pen 6 | I38: Active | O38: =IFERROR(VLOOKUP($A38,BREED_MIX!$A$2:$AB$61,2,FALSE),"") | P38: =IFERROR(VLOOKUP($A38,BREED_MIX!$A$2:$AB$61,25,FALSE),"") | Q38: =IFERROR(VLOOKUP($A38,BREED_MIX!$A$2:$AB$61,26,FALSE),"") | R38: =IFERROR(VLOOKUP($A38,BREED_MIX!$A$2:$AB$61,27,FALSE),"") | S38: =IF($A38="","",IF(AND($J38<>"",$K38<>""),2,IF(OR($J38<>"",$K38<>""),1,0))) | T38: fat tail
A39: TAG_0056 | B39: 0056 | C39: 0056 | D39: E | F39: =IF($E39="","",YEAR($E39)) | G39: =IF($E39="","",IF(('WEIGHTS_&_RULES'!$B$3-$E39)<365,"Lamb",IF(('WEIGHTS_&_RULES'!$B$3-$E39)<730,"Yearling","Adult"))) | H39: Pen 6 | I39: Active | O39: =IFERROR(VLOOKUP($A39,BREED_MIX!$A$2:$AB$61,2,FALSE),"") | P39: =IFERROR(VLOOKUP($A39,BREED_MIX!$A$2:$AB$61,25,FALSE),"") | Q39: =IFERROR(VLOOKUP($A39,BREED_MIX!$A$2:$AB$61,26,FALSE),"") | R39: =IFERROR(VLOOKUP($A39,BREED_MIX!$A$2:$AB$61,27,FALSE),"") | S39: =IF($A39="","",IF(AND($J39<>"",$K39<>""),2,IF(OR($J39<>"",$K39<>""),1,0))) | T39: fat tail
A40: TAG_0055 | B40: 0055 | C40: 0055 | D40: E | F40: =IF($E40="","",YEAR($E40)) | G40: =IF($E40="","",IF(('WEIGHTS_&_RULES'!$B$3-$E40)<365,"Lamb",IF(('WEIGHTS_&_RULES'!$B$3-$E40)<730,"Yearling","Adult"))) | H40: Pen 6 | I40: Active | O40: =IFERROR(VLOOKUP($A40,BREED_MIX!$A$2:$AB$61,2,FALSE),"") | P40: =IFERROR(VLOOKUP($A40,BREED_MIX!$A$2:$AB$61,25,FALSE),"") | Q40: =IFERROR(VLOOKUP($A40,BREED_MIX!$A$2:$AB$61,26,FALSE),"") | R40: =IFERROR(VLOOKUP($A40,BREED_MIX!$A$2:$AB$61,27,FALSE),"") | S40: =IF($A40="","",IF(AND($J40<>"",$K40<>""),2,IF(OR($J40<>"",$K40<>""),1,0))) | T40: fat tail
...

Sheet BREED_SUPERSET
A1: Breed (superset) | B1: Avg mature wt (EWE, lb) | C1: Avg mature wt (RAM, lb) | D1: Hair breed? (Y/N) | E1: Notes
A2: American Black Belly | B2: 115 | C2: 135 | D2: Y
A3: Awassi | B3: 200 | C3: 310 | D3: N
A4: Babydoll | B4: 80 | C4: 125 | D4: N
A5: Barbados Black Belly | B5: 95 | C5: 125 | D5: Y
A6: Black Headed Dorper | B6: 200 | C6: 300 | D6: Y
A7: Cotswald | B7: 200 | C7: 300 | D7: N
A8: Cracker | B8: 110 | C8: 225 | D8: N
A9: East Friesan | B9: 210 | C9: 275 | D9: N
A10: Gulf Coast Native | B10: 125 | C10: 165 | D10: N
A11: Hampshire | B11: 200 | C11: 275 | D11: N
A12: Jacob | B12: 100 | C12: 150 | D12: N
A13: Karakul
A14: Katahdin | B14: 140 | C14: 235 | D14: Y
A15: Southdown | B15: 200 | C15: 350 | D15: N
A16: St Augustine | B16: 200 | C16: 300 | D16: Y
A17: St Croix | B17: 150 | C17: 200 | D17: Y
A18: Suffolk | B18: 253 | C18: 330 | D18: N
A19: Texel | B19: 185 | C19: 240 | D19: N
A20: Tunis | B20: 160 | C20: 275 | D20: N
A21: White Dorper | B21: 185 | C21: 235 | D21: Y
A22: Wiltshire Horn | B22: 150 | C22: 300 | D22: Y
A28: FM | D28: N | E28: From Manatee Creek - Weights and Averages.csv
A29: FM 1 | D29: N | E29: From Manatee Creek - Weights and Averages.csv
A30: Nori | D30: N | E30: From Manatee Creek - Weights and Averages.csv
A31: Eclipse | D31: N | E31: From Manatee Creek - Weights and Averages.csv
A32: FM1 x Eclipse | D32: N | E32: From Manatee Creek - Weights and Averages.csv
A33: Shaggy | D33: N | E33: From Manatee Creek - Weights and Averages.csv
A34: Sir Loin | D34: N | E34: From Manatee Creek - Weights and Averages.csv
A35: Serendipity | D35: N | E35: From Manatee Creek - Weights and Averages.csv
A36: Kaladin | D36: N | E36: From Manatee Creek - Weights and Averages.csv

Sheet BREED_MIX
A1: AnimalID* | B1: % Hair (optional) | C1: % American Black Belly | D1: % Awassi | E1: % Babydoll | F1: % Barbados Black Belly | G1: % Black Headed Dorper | H1: % Cotswald | I1: % Cracker | J1: % East Friesan | K1: % Gulf Coast Native | L1: % Hampshire | M1: % Jacob | N1: % Karakul | O1: % Katahdin | P1: % Southdown | Q1: % St Augustine | R1: % St Croix | S1: % Suffolk | T1: % Texel | U1: % Tunis | V1: % White Dorper | W1: % Wiltshire Horn | X1: Sum % | Y1: Expected mature wt (EWE, lb) | Z1: Expected mature wt (RAM, lb) | AA1: Primary Breed | AB1: Notes
A2: MERRIE | B2: 100 | C2: 0 | D2: 0 | E2: 0 | F2: 6.25 | G2: 0 | H2: 0 | I2: 50 | J2: 0 | K2: 0 | L2: 0 | M2: 0 | N2: 0 | O2: 12.5 | P2: 0 | Q2: 28.125 | R2: 0 | S2: 0 | T2: 0 | U2: 0 | V2: 3.125 | W2: 0 | X2: =IF($A2="","",SUM(C2:W2)) | Y2: =IF($A2="","",SUMPRODUCT(C2:W2,BREED_SUPERSET!$B$2:$B$22)/100) | Z2: =IF($A2="","",SUMPRODUCT(C2:W2,BREED_SUPERSET!$C$2:$C$22)/100) | AA2: Cracker | AB2: Imported from paste/CSV; verify if conflicts
A3: ELSIE | C3: 6.25 | D3: 0 | E3: 0 | F3: 0 | G3: 0 | H3: 0 | I3: 0 | J3: 0 | K3: 0 | L3: 0 | M3: 0 | N3: 0 | O3: 65.625 | P3: 0 | Q3: 28.125 | R3: 0 | S3: 0 | T3: 0 | U3: 0 | V3: 0 | W3: 0 | X3: =IF($A3="","",SUM(C3:W3)) | Y3: =IF($A3="","",SUMPRODUCT(C3:W3,BREED_SUPERSET!$B$2:$B$22)/100) | Z3: =IF($A3="","",SUMPRODUCT(C3:W3,BREED_SUPERSET!$C$2:$C$22)/100) | AA3: Southdown | AB3: Imported from paste/CSV; verify if conflicts
A4: BROKEN_TAIL | C4: 0 | D4: 0 | E4: 0 | F4: 0 | G4: 0 | H4: 0 | I4: 0 | J4: 0 | K4: 0 | L4: 0 | M4: 0 | N4: 0 | O4: 28.125 | P4: 0 | Q4: 65.625 | R4: 0 | S4: 0 | T4: 0 | U4: 0 | V4: 0 | W4: 0 | X4: =IF($A4="","",SUM(C4:W4)) | Y4: =IF($A4="","",SUMPRODUCT(C4:W4,BREED_SUPERSET!$B$2:$B$22)/100) | Z4: =IF($A4="","",SUMPRODUCT(C4:W4,BREED_SUPERSET!$C$2:$C$22)/100) | AA4: Black Headed Dorper | AB4: Imported from paste/CSV; verify if conflicts
A5: BUCK_2433 | C5: 0 | D5: 48 | E5: 0 | F5: 0 | G5: 0 | H5: 0 | I5: 0 | J5: 2 | K5: 0 | L5: 0 | M5: 0 | N5: 0 | O5: 50 | P5: 0 | Q5: 0 | R5: 0 | S5: 0 | T5: 0 | U5: 0 | V5: 0 | W5: 0 | X5: =IF($A5="","",SUM(C5:W5)) | Y5: =IF($A5="","",SUMPRODUCT(C5:W5,BREED_SUPERSET!$B$2:$B$22)/100) | Z5: =IF($A5="","",SUMPRODUCT(C5:W5,BREED_SUPERSET!$C$2:$C$22)/100) | AA5: Katahdin | AB5: Imported from paste/CSV; verify if conflicts
A6: SIRLOIN | C6: 0 | D6: 0 | E6: 0 | F6: 0 | G6: 0 | H6: 0 | I6: 0 | J6: 0 | K6: 0 | L6: 0 | M6: 0 | N6: 0 | O6: 25 | P6: 0 | Q6: 75 | R6: 0 | S6: 0 | T6: 0 | U6: 0 | V6: 0 | W6: 0 | X6: =IF($A6="","",SUM(C6:W6)) | Y6: =IF($A6="","",SUMPRODUCT(C6:W6,BREED_SUPERSET!$B$2:$B$22)/100) | Z6: =IF($A6="","",SUMPRODUCT(C6:W6,BREED_SUPERSET!$C$2:$C$22)/100) | AB6: Imported from paste/CSV; verify if conflicts
W7: 0 | X7: =IF($A7="","",SUM(C7:W7)) | Y7: =IF($A7="","",SUMPRODUCT(C7:W7,BREED_SUPERSET!$B$2:$B$22)/100) | Z7: =IF($A7="","",SUMPRODUCT(C7:W7,BREED_SUPERSET!$C$2:$C$22)/100)
W8: 0 | X8: =IF($A8="","",SUM(C8:W8)) | Y8: =IF($A8="","",SUMPRODUCT(C8:W8,BREED_SUPERSET!$B$2:$B$22)/100) | Z8: =IF($A8="","",SUMPRODUCT(C8:W8,BREED_SUPERSET!$C$2:$C$22)/100)
W9: 0 | X9: =IF($A9="","",SUM(C9:W9)) | Y9: =IF($A9="","",SUMPRODUCT(C9:W9,BREED_SUPERSET!$B$2:$B$22)/100) | Z9: =IF($A9="","",SUMPRODUCT(C9:W9,BREED_SUPERSET!$C$2:$C$22)/100)
W10: 0 | X10: =IF($A10="","",SUM(C10:W10)) | Y10: =IF($A10="","",SUMPRODUCT(C10:W10,BREED_SUPERSET!$B$2:$B$22)/100) | Z10: =IF($A10="","",SUMPRODUCT(C10:W10,BREED_SUPERSET!$C$2:$C$22)/100)
W11: 0 | X11: =IF($A11="","",SUM(C11:W11)) | Y11: =IF($A11="","",SUMPRODUCT(C11:W11,BREED_SUPERSET!$B$2:$B$22)/100) | Z11: =IF($A11="","",SUMPRODUCT(C11:W11,BREED_SUPERSET!$C$2:$C$22)/100)
W12: 0 | X12: =IF($A12="","",SUM(C12:W12)) | Y12: =IF($A12="","",SUMPRODUCT(C12:W12,BREED_SUPERSET!$B$2:$B$22)/100) | Z12: =IF($A12="","",SUMPRODUCT(C12:W12,BREED_SUPERSET!$C$2:$C$22)/100)
W13: 0 | X13: =IF($A13="","",SUM(C13:W13)) | Y13: =IF($A13="","",SUMPRODUCT(C13:W13,BREED_SUPERSET!$B$2:$B$22)/100) | Z13: =IF($A13="","",SUMPRODUCT(C13:W13,BREED_SUPERSET!$C$2:$C$22)/100)
W14: 0 | X14: =IF($A14="","",SUM(C14:W14)) | Y14: =IF($A14="","",SUMPRODUCT(C14:W14,BREED_SUPERSET!$B$2:$B$22)/100) | Z14: =IF($A14="","",SUMPRODUCT(C14:W14,BREED_SUPERSET!$C$2:$C$22)/100)
W15: 0 | X15: =IF($A15="","",SUM(C15:W15)) | Y15: =IF($A15="","",SUMPRODUCT(C15:W15,BREED_SUPERSET!$B$2:$B$22)/100) | Z15: =IF($A15="","",SUMPRODUCT(C15:W15,BREED_SUPERSET!$C$2:$C$22)/100)
W16: 0 | X16: =IF($A16="","",SUM(C16:W16)) | Y16: =IF($A16="","",SUMPRODUCT(C16:W16,BREED_SUPERSET!$B$2:$B$22)/100) | Z16: =IF($A16="","",SUMPRODUCT(C16:W16,BREED_SUPERSET!$C$2:$C$22)/100)
W17: 0 | X17: =IF($A17="","",SUM(C17:W17)) | Y17: =IF($A17="","",SUMPRODUCT(C17:W17,BREED_SUPERSET!$B$2:$B$22)/100) | Z17: =IF($A17="","",SUMPRODUCT(C17:W17,BREED_SUPERSET!$C$2:$C$22)/100)
W18: 0 | X18: =IF($A18="","",SUM(C18:W18)) | Y18: =IF($A18="","",SUMPRODUCT(C18:W18,BREED_SUPERSET!$B$2:$B$22)/100) | Z18: =IF($A18="","",SUMPRODUCT(C18:W18,BREED_SUPERSET!$C$2:$C$22)/100)
... W61: 0 | X61: =IF($A61="","",SUM(C61:W61)) | Y61: =IF($A61="","",SUMPRODUCT(C61:W61,BREED_SUPERSET!$B$2:$B$22)/100) | Z61: =IF($A61="","",SUMPRODUCT(C61:W61,BREED_SUPERSET!$C$2:$C$22)/100)
A62: TAG_02241 | O62: 100
A63: KAT_X_AWASSI | D63: 48 | J63: 2 | O63: 50
A64: OAV_2223_2 | O64: 100
A65: FL51870_0502_PEN_1_2 | L65: 50 | S65: 50
A66: OAV_2222_2 | O66: 100
A67: SERENDIPITY | E67: 25 | M67: 25 | O67: 12.5 | Q67: 37.5
A68: NORI_0029 | C68: 50 | W68: 50
